Workbook

Sheet PRODUCT
A2: Worksheet 1:
A4: ProductID | B4: Product | C4: Price
A5: 101 | B5: Product A | C5: 120
A6: 102 | B6: Product B | C6: 150
A7: 103 | B7: Product C | C7: 200
A8: 104 | B8: Product D | C8: 90
A9: 105 | B9: Product E | C9: 220
A10: 106 | B10: Product F | C10: 130

Sheet ORDERS
K2: 1.Use VLOOKUP to find the Product Names of each Product ID in the Orders Worksheet .
B4: Order ID | C4: Product ID | D4: Quantity | E4: Total Price | K4: Order ID | L4: Product ID | M4: Quantity | N4: product Name
B5: 1 | C5: 101 | D5: 2 | K5: 1 | L5: 101 | M5: 2 | N5: =VLOOKUP(L5,PRODUCT!$A$4:$C$10,2,0) -> Product A
B6: 2 | C6: 103 | D6: 1 | K6: 2 | L6: 103 | M6: 1 | N6: =VLOOKUP(L6,PRODUCT!$A$4:$C$10,2,0) -> Product C
B7: 3 | C7: 105 | D7: 4 | K7: 3 | L7: 105 | M7: 4 | N7: =VLOOKUP(L7,PRODUCT!$A$4:$C$10,2,0) -> Product E
B8: 4 | C8: 106 | D8: 3 | K8: 4 | L8: 106 | M8: 3 | N8: =VLOOKUP(L8,PRODUCT!$A$4:$C$10,2,0) -> Product F
B9: 5 | C9: 102 | D9: 5 | K9: 5 | L9: 102 | M9: 5 | N9: =VLOOKUP(L9,PRODUCT!$A$4:$C$10,2,0) -> Product B
B10: 6 | C10: 104 | D10: 6 | K10: 6 | L10: 104 | M10: 6 | N10: =VLOOKUP(L10,PRODUCT!$A$4:$C$10,2,0) -> Product D
A13: 1. Use VLOOKUP to find the product names for each ProductID in the Orders
A14: worksheet. | K14: 2.Use VLOOKUP to find thr Price for each ProductID in the Orders worksheet, then
A15: 2. Use VLOOKUP to find the price for each ProductID in the Orders worksheet, then
A16: calculate the TotalPrice by multiplying the Quantity by the Product Price.
A17: 3. Use VLOOKUP to check if there are any ProductIDs in the Orders worksheet that | K17: Order ID | L17: Product ID | M17: Quantity | N17: Price | O17: Toltal Price
A18: do not exist in the Products worksheet. | K18: 1 | L18: 101 | M18: 2 | N18: =VLOOKUP(L18,PRODUCT!$A$4:$C$10,3,0) -> 120 | O18: =M18*N18 -> 240
A19: 4. Assume a discount of 10% is given on all products. Use VLOOKUP to find the | K19: 2 | L19: 103 | M19: 1 | N19: =VLOOKUP(L19,PRODUCT!$A$4:$C$10,3,0) -> 200 | O19: =M19*N19 -> 200
A20: original price and then calculate the discounted price. | K20: 3 | L20: 105 | M20: 4 | N20: =VLOOKUP(L20,PRODUCT!$A$4:$C$10,3,0) -> 220 | O20: =M20*N20 -> 880
A21: 5. Use VLOOKUP to find the price for each ProductID and then calculate the order | K21: 4 | L21: 106 | M21: 3 | N21: =VLOOKUP(L21,PRODUCT!$A$4:$C$10,3,0) -> 130 | O21: =M21*N21 -> 390
A22: value. Find the maximum order value from the list. | K22: 5 | L22: 102 | M22: 5 | N22: =VLOOKUP(L22,PRODUCT!$A$4:$C$10,3,0) -> 150 | O22: =M22*N22 -> 750
A23: 6. Use VLOOKUP to find out which products from the Products worksheet have not | K23: 6 | L23: 104 | M23: 6 | N23: =VLOOKUP(L23,PRODUCT!$A$4:$C$10,3,0) -> 90 | O23: =M23*N23 -> 540
A24: been ordered.
A25: 7. Use VLOOKUP to find the Product name and summarize the total quantity sold
A26: for each product. | K26: 3. Use VLOOKUP to check if there are any Product IDs in the Orders
K27: worksheet that do not exist in the Products Worksheet.
K29: Order ID | L29: Product ID | M29: Quantity | N29: Result
K30: 1 | L30: 101 | M30: 2 | N30: =IF(ISNA(VLOOKUP(L30,PRODUCT!$A$4:$B$10,1,0)),"Not Exist","Exist") -> Exist
K31: 2 | L31: 103 | M31: 1 | N31: =IF(ISNA(VLOOKUP(L31,PRODUCT!$A$4:$B$10,1,0)),"Not Exist","Exist") -> Exist
K32: 3 | L32: 105 | M32: 4 | N32: =IF(ISNA(VLOOKUP(L32,PRODUCT!$A$4:$B$10,1,0)),"Not Exist","Exist") -> Exist
K33: 4 | L33: 106 | M33: 3 | N33: =IF(ISNA(VLOOKUP(L33,PRODUCT!$A$4:$B$10,1,0)),"Not Exist","Exist") -> Exist
K34: 5 | L34: 102 | M34: 5 | N34: =IF(ISNA(VLOOKUP(L34,PRODUCT!$A$4:$B$10,1,0)),"Not Exist","Exist") -> Exist
K35: 6 | L35: 104 | M35: 6 | N35: =IF(ISNA(VLOOKUP(L35,PRODUCT!$A$4:$B$10,1,0)),"Not Exist","Exist") -> Exist
K36: 7 | L36: 108 | M36: 8 | N36: =IF(ISNA(VLOOKUP(L36,PRODUCT!$A$4:$B$10,1,0)),"Not Exist","Exist") -> Not Exist
K41: 4.Calculate Discounted Price (10% off)
K43: Product | L43: Original Price | M43: Discounted Price
K44: Product A | L44: 120 | M44: =L44*0.9 -> 108
K45: Product B | L45: 150 | M45: =L45*0.9 -> 135
K46: Product C | L46: 200 | M46: =L46*0.9 -> 180
K47: Product D | L47: 90 | M47: =L47*0.9 -> 81
K48: Product E | L48: 220 | M48: =L48*0.9 -> 198
K49: Product F | L49: 130 | M49: =L49*0.9 -> 117
K52: 5.Maximum Order Value
...
